Workbook

Sheet Overview
A1: Date | B1: Training_Name | C1: # Registrations | D1: m+f+d | E1: # Participants | F1: Attend_Rate | G1: Male | H1: Female | I1: Diverse | J1: Female % | K1: ECS | L1: ECS % | M1: SME | N1: SME % | O1: Familar? | P1: Familiar? % | Q1: FeedbackF | R1: FeedbackF % | S1: wideningC | T1: wideningC % | U1: #Scientific fields | V1: #Countries | W1: non-EU | X1: non-EU % | Y1: America
A2: 45200 | B2: EPOSMetadata | C2: {=COUNT(INDIRECT(B2&"!A$2:A$1000"))} -> 89 | D2: =G2+H2+I2 -> 89 | E2: 81 | F2: =E2/C2 -> 0.91011236 | G2: {=COUNTIF(INDIRECT($B2&"!B$2:B$1000"),"Male")} -> 43 | H2: {=COUNTIF(INDIRECT($B2&"!B$2:B$1000"),"Female")} -> 44 | I2: {=COUNTIF(INDIRECT($B2&"!B$2:B$1000"),"Diverse")} -> 2 | J2: =H2/C2 -> 0.49438202 | K2: {=COUNTIF(INDIRECT($B2&"!E$2:E$1000"),"Yes")} -> 36 | L2: =K2/C2 -> 0.40449438 | M2: {=COUNTIF(INDIRECT($B2&"!F$2:F$1000"),"Yes")} -> 7 | N2: =M2/C2 -> 0.078651685 | O2: {=COUNTIF(INDIRECT($B2&"!I$2:I$1000"),"Yes")} -> 39 | P2: =O2/C2 -> 0.43820225 | Q2: 19 | R2: =Q2/E2 -> 0.2345679 | S2: 15 | T2: =S2/C2 -> 0.16853933 | U2: 18 | V2: 22 | W2: 6 | X2: =W2/C2 -> 0.06741573
A3: 45315 | B3: EPOS Data Portal Trg | C3: 399 | D3: =G3+H3+I3 -> 399 | E3: 212 | F3: =E3/C3 -> 0.53132832 | G3: 187 | H3: 212 | I3: 0 | J3: =H3/C3 -> 0.53132832 | K3: 25 | L3: =K3/C3 -> 0.062656642 | M3: 13 | N3: =M3/C3 -> 0.032581454 | Q3: 69 | R3: =Q3/C3 -> 0.17293233 | S3: 12 | T3: =S3/Q3 -> 0.17391304 | U3: 16 | V3: 34 | W3: 13 | X3: =W3/C3 -> 0.032581454
A4: 45413 | B4: EPOS Data Portal Trg 2 | C4: 103 | D4: =G4+H4+I4 -> 65 | E4: 65 | F4: =E4/C4 -> 0.63106796 | G4: 32 | H4: 33 | I4: 0 | J4: =H4/C4 -> 0.32038835 | K4: 13 | L4: =K4/C4 -> 0.12621359 | M4: 0 | N4: 0 | O4: 22 | P4: =O4/C4 -> 0.21359223 | Q4: 33 | R4: =Q4/C4 -> 0.32038835 | S4: 7 | T4: =S4/C4 -> 0.067961165 | U4: 14 | V4: 28 | W4: 8 | X4: =W4/C4 -> 0.077669903
A5: Oct-24 | B5: EPOS Data Portal Trg 3 | C5: 72 | D5: =G5+H5+I5 -> 72 | E5: 44 | F5: =E5/C5 -> 0.61111111 | G5: 25 | H5: 47 | I5: 0 | J5: =H5/C5 -> 0.65277778 | K5: 3 | L5: =K5/C5 -> 0.041666667 | M5: 0 | N5: 0 | O5: 10 | P5: =O5/C5 -> 0.13888889 | Q5: 24 | R5: =Q5/C5 -> 0.33333333 | S5: 39 | T5: =S4/C4 -> 0.067961165 | U5: =AVERAGE(U2:U4) -> 16 | V5: 20 | W5: 2 | X5: =W5/C5 -> 0.027777778
A6: Mar-2025 | B6: EPOS Platform Trg - Online 12-03-2025 | C6: 90 | D6: 37 | E6: 17 | F6: =E6/C6 -> 0.18888889 | G6: 8 | H6: 9 | I6: 0 | J6: 0.53 | K6: 3 | L6: 0.18 | M6: 0 | N6: 0 | O6: 5 | P6: 0.29 | Q6: 17 | R6: =Q6/C6 -> 0.18888889 | S6: 0 | T6: 0 | U6: 14 | V6: 6 | W6: 0 | X6: 0
A7: 45748 | B7: EPOS Platform Trg - EGU25 | C7: =E7 -> 21 | D7: 21 | E7: 21 | F7: =E7/C7 -> 1 | G7: 3 | H7: 5 | I7: 0 | J7: 0.62 | K7: 4 | L7: 0.5 | M7: 0 | N7: 0 | O7: 3 | P7: 0.38 | Q7: 8 | R7: =Q7/D7 -> 0.38095238 | S7: 1 | T7: 0.13 | U7: 10 | V7: 6 | W7: 0 | X7: 0
A8: May-2025 | B8: EPOS Platform Trg - Clermont-Ferrand | C8: =E8 -> 8 | D8: 8 | E8: 8 | F8: =E8/C8 -> 1 | G8: 4 | H8: 4 | I8: 0 | J8: 0.5 | K8: 3 | L8: 0.38 | M8: 0 | N8: 0 | O8: 3 | P8: 0.38 | Q8: 8 | R8: 1 | S8: 0 | T8: 0 | U8: 9 | V8: 1 | W8: 0 | X8: 0
A9: May-2025 | B9: EPOS Platform Trg - S4E | C9: =E9 -> 6 | D9: 6 | E9: 6 | F9: =E9/C9 -> 1 | G9: 3 | H9: 3 | I9: 0 | J9: 0.5 | K9: 4 | L9: 0.67 | M9: 0 | N9: 0 | O9: 1 | P9: 0.17 | Q9: 6 | R9: 0.75 | S9: 0 | T9: 0 | U9: 4 | V9: 2 | W9: 0 | X9: 0
A10: Jun-2025 | B10: EPOS Platform Trg - EPOS Summer School | C10: =E10 -> 25 | D10: 25 | E10: 25 | F10: =E10/C10 -> 1 | G10: 8 | H10: 17 | I10: 0 | J10: 0.68 | K10: 13 | L10: 0.52 | M10: 0 | N10: 0 | O10: 10 | P10: 0.4 | Q10: 25 | R10: 1 | S10: 5 | T10: 0.2 | U10: 19 | V10: 15 | W10: 6 | X10: 0.24
A11: July-2025 | B11: EPOS Platform Trg - Spain | C11: =E11 -> 26 | D11: 26 | E11: 26 | F11: =E11/C11 -> 1 | G11: 12 | H11: 14 | I11: 0 | J11: 0.54 | K11: 10 | L11: 0.38 | M11: 0 | N11: 0 | O11: 10 | P11: 0.38 | Q11: 26 | R11: 1 | S11: 1 | T11: 0.04 | U11: 20 | V11: 2 | W11: 0 | X11: 0
A12: Sep-2025 | B12: EPOS Platform Trg - CZ | C12: =E12 -> 9 | D12: 9 | E12: 9 | F12: =E12/C12 -> 1 | G12: 8 | H12: 1 | I12: 0 | J12: 0.11 | K12: 2 | L12: 0.29 | M12: 0 | N12: 0 | O12: 4 | P12: 0.44 | Q12: 7 | R12: 0.88 | S12: 6 | T12: 0.14 | U12: 21 | V12: 2 | W12: 0 | X12: 0
A13: May-2026 | B13: EPOS Platform Trg - EGU26 | C13: 10 | D13: 10 | E13: 10 | F13: 1 | G13: 5 | H13: 5 | I13: 0 | J13: 0.5 | K13: 2 | L13: =K13/D13 -> 0.2 | M13: 2 | N13: 0.2 | O13: 1 | P13: 0.1 | Q13: 2 | R13: 0.2
A14: May-2026 | B14: EPOS Platform Trg - CZ | C14: 7 | D14: 7 | E14: 7 | F14: 1 | G14: 4 | H14: 3 | I14: 0 | J14: =H14/C14 -> 0.42857143 | K14: 2 | L14: =K14/C14 -> 0.28571429 | M14: 0 | N14: 0 | O14: 2 | P14: =O14/C14 -> 0.28571429 | Q14: 7 | R14: 1 | S14: 0 | T14: 0 | U14: 9 | V14: 1 | W14: 0 | X14: 0
A15: Summary | B15: 11 EPOS Trg | C15: =SUM(C2:C14) -> 865 | D15: =SUM(D2:D14) -> 774 | E15: =SUM(E2:E14) -> 531 | F15: =E15/C15 -> 0.61387283 | G15: =SUM(G2:G14) -> 342 | H15: =SUM(H2:H14) -> 397 | I15: =SUM(I2:I14) -> 2 | J15: =H15/(G15+H15+I15) -> 0.53576248 | K15: =SUM(K2:K14) -> 120 | L15: =K15/C15 -> 0.13872832 | M15: =SUM(M2:M14) -> 22 | N15: =M15/C15 -> 0.025433526 | O15: =SUM(O2:O14) -> 110 | P15: =O15/(C15-C3) -> 0.2360515
B16: .
A17: 45047 | B17: HPS-SCOPED1 | C17: 205 | D17: =G17+H17+I17 -> 205 | E17: 134 | F17: =E17/C17 -> 0.65365854 | G17: 128 | H17: 70 | I17: 7 | J17: =H17/C17 -> 0.34146341 | K17: 84 | L17: =K17/C17 -> 0.4097561 | M17: 15 | N17: =M17/C17 -> 0.073170732 | O17: 186 | P17: =O17/C17 -> 0.90731707 | S17: 10 | T17: =S17/C17 -> 0.048780488 | U17: 4 | V17: 33 | W17: 113 | X17: =W17/C17 -> 0.55121951 | Y17: 90
A18: 45231 | B18: ETRiS | C18: =COUNT(INDIRECT(B18&"!A$2:A$1000")) -> 234 | D18: =G18+H18+I18 -> 234 | E18: 144 | F18: =E18/C18 -> 0.61538462 | G18: =COUNTIF(INDIRECT($B18&"!B$2:B$1000"),"Male") -> 145 | H18: =COUNTIF(INDIRECT($B18&"!B$2:B$1000"),"Female") -> 89 | I18: =COUNTIF(INDIRECT($B18&"!B$2:B$1000"),"Diverse") -> 0 | J18: =H18/C18 -> 0.38034188 | K18: =COUNTIF(INDIRECT($B18&"!E$2:E$1000"),"Yes") -> 171 | L18: =K18/C18 -> 0.73076923 | M18: =COUNTIF(INDIRECT($B18&"!F$2:F$1000"),"Yes") -> 67 | N18: =M18/C18 -> 0.28632479 | O18: =COUNTIF(INDIRECT($B18&"!I$2:I$1000"),"Yes") -> 3 | P18: =O18/C18 -> 0.012820513 | Q18: 28 | R18: =Q18/E18 -> 0.19444444 | S18: 20 | T18: =S18/C18 -> 0.085470085 | U18: 27 | V18: 46 | W18: 109 | X18: =W18/C18 -> 0.46581197
A19: 45383 | B19: HySEA_T | C19: =COUNT(INDIRECT(B19&"!A$2:A$1000")) -> 66 | D19: =G19+H19+I19 -> 66 | E19: 57 | F19: =E19/C19 -> 0.86363636 | G19: =COUNTIF(INDIRECT($B19&"!B$2:B$1000"),"Male") -> 37 | H19: =COUNTIF(INDIRECT($B19&"!B$2:B$1000"),"Female") -> 27 | I19: =COUNTIF(INDIRECT($B19&"!B$2:B$1000"),"Diverse") -> 2 | J19: =H19/C19 -> 0.40909091 | K19: =COUNTIF(INDIRECT($B19&"!E$2:E$1000"),"Yes") -> 46 | L19: =K19/C19 -> 0.6969697 | M19: =COUNTIF(INDIRECT($B19&"!F$2:F$1000"),"Yes") -> 7 | N19: =M19/C19 -> 0.10606061 | O19: =COUNTIF(INDIRECT($B19&"!I$2:I$1000"),"Yes") -> 16 | P19: =O19/C19 -> 0.24242424 | Q19: 20 | R19: =Q19/E19 -> 0.35087719 | S19: 3 | T19: =S19/C19 -> 0.045454545 | U19: 15 | V19: 19 | W19: 31 | X19: =W19/C19 -> 0.46969697
A20: 45754 | B20: HySEA_L | C20: =COUNT(INDIRECT(B20&"!A$2:A$1000")) -> 105 | D20: =G20+H20+I20 -> 105 | E20: 79 | F20: =E20/C20 -> 0.75238095 | G20: =COUNTIF(INDIRECT($B20&"!B$2:B$1000"),"Male") -> 64 | H20: =COUNTIF(INDIRECT($B20&"!B$2:B$1000"),"Female") -> 40 | I20: =COUNTIF(INDIRECT($B20&"!B$2:B$1000"),"Diverse") -> 1 | J20: =H20/C20 -> 0.38095238 | K20: =COUNTIF(INDIRECT($B20&"!E$2:E$1000"),"Yes") -> 74 | L20: =K20/C20 -> 0.7047619 | M20: =COUNTIF(INDIRECT($B20&"!F$2:F$1000"),"Yes") -> 14 | N20: =M20/C20 -> 0.13333333 | P20: =O20/C20 -> 0 | Q20: 6 | R20: =Q20/E20 -> 0.075949367 | S20: 21 | T20: =S20/C20 -> 0.2 | U20: 12 | V20: 28 | W20: 48 | X20: =W20/C20 -> 0.45714286
A21: 45536 | B21: PyBET | C21: 18 | D21: =G21+H21+I21 -> 18 | E21: 18 | F21: =E21/C21 -> 1 | G21: =COUNTIF(INDIRECT($B21&"!B$2:B$1000"),"Male") -> 13 | H21: =COUNTIF(INDIRECT($B21&"!B$2:B$1000"),"Female") -> 5 | I21: =COUNTIF(INDIRECT($B21&"!B$2:B$1000"),"Diverse") -> 0 | J21: =H21/C21 -> 0.27777778 | K21: =COUNTIF(INDIRECT($B21&"!E$2:E$1000"),"Yes") -> 13 | L21: =K21/C21 -> 0.72222222 | M21: =COUNTIF(INDIRECT($B21&"!F$2:F$1000"),"Yes") -> 1 | N21: =M21/C21 -> 0.055555556 | O21: =COUNTIF(INDIRECT($B21&"!I$2:I$1000"),"Yes") -> 2 | P21: =O21/C21 -> 0.11111111 | Q21: 5 | R21: =Q21/E21 -> 0.27777778 | S21: 2 | T21: =S21/C21 -> 0.11111111 | U21: 8 | V21: 11 | W21: 11 | X21: =W21/C21 -> 0.61111111 | Z21: preliminary results from feedback, survey still open
A22: 45536 | B22: SDL_WS | C22: 130 | D22: =G22+H22+I22 -> 126 | E22: 126 | F22: =E22/C22 -> 0.96923077 | G22: =COUNTIF(INDIRECT($B22&"!B$2:B$1000"),"Male") -> 73 | H22: =COUNTIF(INDIRECT($B22&"!B$2:B$1000"),"Female") -> 53 | I22: =COUNTIF(INDIRECT($B22&"!B$2:B$1000"),"Diverse") -> 0 | J22: =H22/C22 -> 0.40769231 | K22: =COUNTIF(INDIRECT($B22&"!E$2:E$1000"),"Yes") -> 61 | L22: =K22/C22 -> 0.46923077 | M22: =COUNTIF(INDIRECT($B22&"!F$2:F$1000"),"Yes") -> 8 | N22: =M22/C22 -> 0.061538462 | O22: =COUNTIF(INDIRECT($B22&"!I$2:I$1000"),"Yes") -> 23 | P22: =O22/C22 -> 0.17692308 | Q22: 21 | R22: =Q22/E22 -> 0.16666667 | S22: 4 | T22: =S22/C22 -> 0.030769231 | U22: 12 | V22: 26 | W22: 42 | X22: =W22/C22 -> 0.32307692 | Z22: preliminary results from feedback, survey still open
A23: 45678 | B23: Quakeworx | C23: {=COUNT(INDIRECT(B23&"!A$2:A$1000"))} -> 149 | D23: =G23+H23+I23 -> 148 | E23: 81 | F23: =E23/C23 -> 0.54362416 | G23: =COUNTIF(INDIRECT($B23&"!B$2:B$1000"),"Male") -> 101 | H23: =COUNTIF(INDIRECT($B23&"!B$2:B$1000"),"Female") -> 44 | I23: =COUNTIF(INDIRECT($B23&"!B$2:B$1000"),"Diverse") -> 3 | J23: =H23/C23 -> 0.29530201 | K23: =COUNTIF(INDIRECT($B23&"!E$2:E$1000"),"Yes") -> 0 | L23: =K23/C23 -> 0 | M23: =COUNTIF(INDIRECT($B23&"!F$2:F$1000"),"Yes") -> 1 | N23: =M23/C23 -> 0.0067114094 | O23: =COUNTIF(INDIRECT($B23&"!I$2:I$1000"),"Yes") -> 14 | P23: =O23/C23 -> 0.093959732 | R23: =Q23/E23 -> 0 | T23: =S23/C23 -> 0 | U23: =AVERAGE(U17:U22) -> 13 | X23: =W23/C23 -> 0
A24: 45897 | B24: VIS_WS | C24: 22 | D24: =G24+H24+I24 -> 16 | E24: 16 | F24: =E24/C24 -> 0.72727273 | G24: =COUNTIF(INDIRECT($B24&"!B$2:B$1000"),"Male") -> 7 | H24: =COUNTIF(INDIRECT($B24&"!B$2:B$1000"),"Female") -> 9 | I24: =COUNTIF(INDIRECT($B24&"!B$2:B$1000"),"Diverse") -> 0 | J24: =H24/C24 -> 0.40909091 | K24: =COUNTIF(INDIRECT($B24&"!E$2:E$1000"),"Yes") -> 14 | L24: =K24/C24 -> 0.63636364 | M24: =COUNTIF(INDIRECT($B24&"!F$2:F$1000"),"Yes") -> 1 | N24: =M24/C24 -> 0.045454545 | O24: =COUNTIF(INDIRECT($B24&"!I$2:I$1000"),"Yes") -> 4 | P24: =O24/C24 -> 0.18181818 | Q24: 7 | R24: =Q24/E24 -> 0.4375 | S24: 3 | T24: =S24/C24 -> 0.13636364 | U24: 14 | V24: 3 | W24: 0 | X24: =W24/C24 -> 0
A25: 45909 | B25: SDL_Trg | C25: 39 | D25: =G25+H25+I25 -> 39 | E25: 30 | F25: =E25/C25 -> 0.76923077 | G25: =COUNTIF(INDIRECT($B25&"!B$2:B$1000"),"Male") -> 21 | H25: =COUNTIF(INDIRECT($B25&"!B$2:B$1000"),"Female") -> 16 | I25: =COUNTIF(INDIRECT($B25&"!B$2:B$1000"),"Diverse") -> 2 | J25: =H25/C25 -> 0.41025641 | K25: =COUNTIF(INDIRECT($B25&"!E$2:E$1000"),"Yes") -> 14 | L25: =K25/C25 -> 0.35897436 | M25: =COUNTIF(INDIRECT($B25&"!F$2:F$1000"),"Yes") -> 7 | N25: =M25/C25 -> 0.17948718 | O25: =COUNTIF(INDIRECT($B25&"!I$2:I$1000"),"Yes") -> 0 | P25: =O25/C25 -> 0 | Q25: 6 | R25: =Q25/E25 -> 0.2 | S25: 6 | T25: =S25/C25 -> 0.15384615 | U25: 14 | V25: 11 | W25: 4 | X25: =W25/C25 -> 0.1025641
A26: June 2026 | B26: SeisSol_ExaHyPE_WS | C26: 59 | D26: =G26+H26+I26 -> 59 | E26: 59 | F26: =E26/C26 -> 1 | G26: =COUNTIF(INDIRECT($B26&"!B$2:B$1000"),"Male") -> 47 | H26: =COUNTIF(INDIRECT($B26&"!B$2:B$1000"),"Female") -> 12 | I26: =COUNTIF(INDIRECT($B26&"!B$2:B$1000"),"Diverse") -> 0 | J26: =H26/C26 -> 0.20338983 | K26: =COUNTIF(INDIRECT($B26&"!E$2:E$1000"),"Yes") -> 34 | L26: =K26/C26 -> 0.57627119 | M26: =COUNTIF(INDIRECT($B26&"!F$2:F$1000"),"Yes") -> 10 | N26: =M26/C26 -> 0.16949153 | O26: =COUNTIF(INDIRECT($B26&"!I$2:I$1000"),"Yes") -> 0 | P26: =O26/C26 -> 0 | Q26: 32 | R26: =Q26/E26 -> 0.54237288 | S26: 4 | T26: =S26/C26 -> 0.06779661 | U26: 14 | V26: 13 | W26: 11 | X26: =W26/C26 -> 0.18644068
A27: Summary | B27: 10 HPC Events | C27: =SUM(C17:C26) -> 1027 | D27: =SUM(D17:D23) -> 902 | E27: =SUM(E17:E26) -> 744 | F27: =E27/C27 -> 0.72444012 | G27: =SUM(G17:G26) -> 636 | H27: =SUM(H17:H26) -> 365 | I27: =SUM(I17:I23) -> 13 | J27: =H27/C27 -> 0.35540409 | K27: =SUM(K17:K23) -> 449 | L27: =K27/C27 -> 0.43719572 | M27: =SUM(M17:M23) -> 113 | N27: =M27/C27 -> 0.11002921 | O27: =SUM(O17:O26) -> 248 | P27: =O27/(C27-C20-C25-C26) -> 0.30097087
B28: .
A29: 45383 | B29: FAIR1 | C29: {=COUNT(INDIRECT(B29&"!A$2:A$1000"))} -> 86 | D29: =G29+H29+I29 -> 86 | E29: 55 | F29: =E29/C29 -> 0.63953488 | G29: =COUNTIF(INDIRECT($B29&"!B$2:B$1000"),"Male") -> 28 | H29: =COUNTIF(INDIRECT($B29&"!B$2:B$1000"),"Female") -> 58 | I29: =COUNTIF(INDIRECT($B29&"!B$2:B$1000"),"Diverse") -> 0 | J29: =H29/C29 -> 0.6744186 | K29: =COUNTIF(INDIRECT($B29&"!E$2:E$1000"),"Yes") -> 40 | L29: =K29/C29 -> 0.46511628 | M29: =COUNTIF(INDIRECT($B29&"!F$2:F$1000"),"Yes") -> 6 | N29: =M29/C29 -> 0.069767442 | O29: =COUNTIF(INDIRECT($B29&"!I$2:I$1000"),"Yes") -> 60 | P29: =O29/C29 -> 0.69767442 | Q29: 9 | R29: =Q29/C29 -> 0.10465116 | S29: 46 | T29: =S29/C29 -> 0.53488372 | U29: 21 | V29: 13 | W29: 3 | X29: =W29/C29 -> 0.034883721
A30: 45444 | B30: FAIR2 | C30: 59 | D30: =G30+H30+I30 -> 59 | E30: 49 | F30: =E30/C30 -> 0.83050847 | G30: =COUNTIF(INDIRECT($B30&"!B$2:B$1000"),"Male") -> 18 | H30: =COUNTIF(INDIRECT($B30&"!B$2:B$1000"),"Female") -> 39 | I30: =COUNTIF(INDIRECT($B30&"!B$2:B$1000"),"Diverse") -> 2 | J30: =H30/C30 -> 0.66101695 | K30: =COUNTIF(INDIRECT($B30&"!E$2:E$1000"),"Yes") -> 25 | L30: =K30/C30 -> 0.42372881 | M30: =COUNTIF(INDIRECT($B30&"!F$2:F$1000"),"Yes") -> 4 | N30: =M30/C30 -> 0.06779661 | O30: =COUNTIF(INDIRECT($B30&"!I$2:I$1000"),"Yes") -> 46 | P30: =O30/C30 -> 0.77966102 | Q30: 13 | R30: =Q30/E30 -> 0.26530612 | S30: 21 | T30: =S30/C30 -> 0.3559322 | U30: 22 | V30: 14 | W30: 3 | X30: =W30/C30 -> 0.050847458
A31: 45580 | B31: FAIR3 | C31: =COUNT(INDIRECT(B31&"!A$2:A$1000")) -> 54 | D31: =G31+H31+I31 -> 54 | E31: 43 | F31: =E31/C31 -> 0.7962963 | G31: =COUNTIF(INDIRECT($B31&"!B$2:B$1000"),"Male") -> 28 | H31: =COUNTIF(INDIRECT($B31&"!B$2:B$1000"),"Female") -> 26 | I31: =COUNTIF(INDIRECT($B31&"!B$2:B$1000"),"Diverse") -> 0 | J31: =H31/C31 -> 0.48148148 | K31: =COUNTIF(INDIRECT($B31&"!E$2:E$1000"),"Yes") -> 28 | L31: =K31/C31 -> 0.51851852 | M31: =COUNTIF(INDIRECT($B31&"!F$2:F$1000"),"Yes") -> 5 | N31: =M31/C31 -> 0.092592593 | O31: =COUNTIF(INDIRECT($B31&"!I$2:I$1000"),"Yes") -> 34 | P31: =O31/C31 -> 0.62962963 | Q31: 13 | R31: =Q31/E31 -> 0.30232558 | S31: 12 | T31: =S31/C31 -> 0.22222222 | U31: 11 | V31: 21 | W31: 9 | X31: =W31/C31 -> 0.16666667
A32: 45622 | B32: FAIR4 | C32: =COUNT(INDIRECT(B32&"!A$2:A$1000")) -> 60 | D32: =G32+H32+I32 -> 60 | E32: 29 | F32: =E32/C32 -> 0.48333333 | G32: =COUNTIF(INDIRECT($B32&"!B$2:B$1000"),"Male") -> 30 | H32: =COUNTIF(INDIRECT($B32&"!B$2:B$1000"),"Female") -> 29 | I32: =COUNTIF(INDIRECT($B32&"!B$2:B$1000"),"Diverse") -> 1 | J32: =H32/C32 -> 0.48333333 | K32: =COUNTIF(INDIRECT($B32&"!E$2:E$1000"),"Yes") -> 13 | L32: =K32/C32 -> 0.21666667 | M32: =COUNTIF(INDIRECT($B32&"!F$2:F$1000"),"Yes") -> 4 | N32: =M32/C32 -> 0.066666667 | O32: =COUNTIF(INDIRECT($B32&"!I$2:I$1000"),"Yes") -> 42 | P32: =O32/C32 -> 0.7 | Q32: 14 | R32: =Q32/E32 -> 0.48275862 | S32: 17 | T32: =S32/C32 -> 0.28333333 | U32: 11 | V32: 18 | W32: 5 | X32: =W32/C32 -> 0.083333333
A33: 45713 | B33: FAIR5 | C33: =COUNT(INDIRECT(B33&"!A$2:A$1000")) -> 54 | D33: =G33+H33+I33 -> 54 | E33: 33 | F33: =E33/C33 -> 0.61111111 | G33: =COUNTIF(INDIRECT($B33&"!B$2:B$1000"),"Male") -> 26 | H33: =COUNTIF(INDIRECT($B33&"!B$2:B$1000"),"Female") -> 28 | I33: =COUNTIF(INDIRECT($B33&"!B$2:B$1000"),"Diverse") -> 0 | J33: =H33/C33 -> 0.51851852 | K33: =COUNTIF(INDIRECT($B33&"!E$2:E$1000"),"Yes") -> 18 | L33: =K33/C33 -> 0.33333333 | M33: =COUNTIF(INDIRECT($B33&"!F$2:F$1000"),"Yes") -> 2 | N33: =M33/C33 -> 0.037037037 | O33: =COUNTIF(INDIRECT($B33&"!I$2:I$1000"),"Yes") -> 40 | P33: =O33/C33 -> 0.74074074 | Q33: 12 | R33: =Q33/E33 -> 0.36363636 | S33: 25 | T33: =S33/C33 -> 0.46296296 | U33: 16 | V33: 15 | W33: 1 | X33: =W33/C33 -> 0.018518519
A34: 45755 | B34: FAIR6 | C34: =COUNT(INDIRECT(B34&"!A$2:A$1000")) -> 33 | D34: =G34+H34+I34 -> 33 | E34: 31 | F34: =E34/C34 -> 0.93939394 | G34: =COUNTIF(INDIRECT($B34&"!B$2:B$1000"),"Male") -> 16 | H34: =COUNTIF(INDIRECT($B34&"!B$2:B$1000"),"Female") -> 17 | I34: =COUNTIF(INDIRECT($B34&"!B$2:B$1000"),"Diverse") -> 0 | J34: =H34/C34 -> 0.51515152 | K34: =COUNTIF(INDIRECT($B34&"!E$2:E$1000"),"Yes") -> 9 | L34: =K34/C34 -> 0.27272727 | M34: =COUNTIF(INDIRECT($B34&"!F$2:F$1000"),"Yes") -> 3 | N34: =M34/C34 -> 0.090909091 | O34: =COUNTIF(INDIRECT($B34&"!I$2:I$1000"),"Yes") -> 26 | P34: =O34/C34 -> 0.78787879 | Q34: 4 | R34: =Q34/E34 -> 0.12903226 | S34: 8 | T34: =S34/C34 -> 0.24242424 | U34: 10 | V34: 10 | W34: 2 | X34: =W34/C34 -> 0.060606061
A35: 45797 | B35: FAIR7 | C35: =COUNT(INDIRECT(B35&"!A$2:A$1000")) -> 20 | D35: =G35+H35+I35 -> 20 | E35: 18 | F35: =E35/C35 -> 0.9 | G35: =COUNTIF(INDIRECT($B35&"!B$2:B$1000"),"Male") -> 9 | H35: =COUNTIF(INDIRECT($B35&"!B$2:B$1000"),"Female") -> 10 | I35: =COUNTIF(INDIRECT($B35&"!B$2:B$1000"),"Diverse") -> 1 | J35: =H35/C35 -> 0.5 | K35: =COUNTIF(INDIRECT($B35&"!E$2:E$1000"),"Yes") -> 7 | L35: =K35/C35 -> 0.35 | M35: =COUNTIF(INDIRECT($B35&"!F$2:F$1000"),"Yes") -> 1 | N35: =M35/C35 -> 0.05 | O35: =COUNTIF(INDIRECT($B35&"!I$2:I$1000"),"Yes") -> 15 | P35: =O35/C35 -> 0.75 | Q35: 3 | R35: =Q35/E35 -> 0.16666667 | S35: 4 | T35: =S35/C35 -> 0.2 | U35: 13 | V35: 9 | W35: 1 | X35: =W35/C35 -> 0.05
A36: Summary | B36: 7 FAIR Trg | C36: =SUM(C29:C35) -> 366 | D36: =SUM(D29:D35) -> 366 | E36: =SUM(E29:E35) -> 258 | F36: =E36/C36 -> 0.70491803 | G36: =SUM(G29:G35) -> 155 | H36: =SUM(H29:H35) -> 207 | I36: =SUM(I29:I35) -> 4 | J36: =H36/C36 -> 0.56557377 | K36: =SUM(K29:K35) -> 140 | L36: =K36/C36 -> 0.38251366 | M36: =SUM(M29:M35) -> 25 | N36: =M36/C36 -> 0.068306011 | O36: =SUM(O29:O35) -> 263 | P36: =O36/C36 -> 0.71857923
B37: .
A38: 45383 | B38: EPISODES_WS | C38: 14 | D38: =G38+H38+I38 -> 14 | E38: 14 | F38: =E38/C38 -> 1 | G38: =COUNTIF(INDIRECT($B38&"!B$2:B$1000"),"Male") -> 9 | H38: =COUNTIF(INDIRECT($B38&"!B$2:B$1000"),"Female") -> 5 | I38: =COUNTIF(INDIRECT($B38&"!B$2:B$1000"),"Diverse") -> 0 | J38: =H38/C38 -> 0.35714286 | K38: =COUNTIF(INDIRECT($B38&"!E$2:E$1000"),"Yes") -> 10 | L38: =K38/C38 -> 0.71428571 | M38: =COUNTIF(INDIRECT($B38&"!F$2:F$1000"),"Yes") -> 6 | N38: =M38/C38 -> 0.42857143 | O38: 8 | P38: =O38/C38 -> 0.57142857 | Q38: 7 | R38: =Q38/C38 -> 0.5 | S38: 13 | T38: =S38/C38 -> 0.92857143 | U38: 13 | V38: 2 | W38: 0 | X38: =W38/C38 -> 0
A39: 45599 | B39: SiteEffects | C39: =COUNT(INDIRECT(B39&"!A$2:A$1000")) -> 50 | D39: =G39+H39+I39 -> 50 | E39: 29 | F39: =E39/C39 -> 0.58 | G39: =COUNTIF(INDIRECT($B39&"!B$2:B$1000"),"Male") -> 29 | H39: =COUNTIF(INDIRECT($B39&"!B$2:B$1000"),"Female") -> 19 | I39: =COUNTIF(INDIRECT($B39&"!B$2:B$1000"),"Diverse") -> 2 | J39: =H39/C39 -> 0.38 | K39: =COUNTIF(INDIRECT($B39&"!E$2:E$1000"),"Yes") -> 33 | L39: =K39/C39 -> 0.66 | M39: =COUNTIF(INDIRECT($B39&"!F$2:F$1000"),"Yes") -> 10 | N39: =M39/C39 -> 0.2 | O39: =COUNTIF(INDIRECT($B39&"!I$2:I$1000"),"Yes") -> 37 | P39: =O39/C39 -> 0.74 | Q39: 8 | R39: =Q39/C39 -> 0.16 | S39: 8 | T39: =S39/C39 -> 0.16 | U39: 12 | V39: 22 | W39: 21 | X39: =W39/C39 -> 0.42
A40: 45600 | B40: SLIP | C40: =COUNT(INDIRECT(B40&"!A$2:A$1000")) -> 89 | D40: =G40+H40+I40 -> 89 | E40: 60 | F40: =E40/C40 -> 0.6741573 | G40: =COUNTIF(INDIRECT($B40&"!B$2:B$1000"),"Male") -> 59 | H40: =COUNTIF(INDIRECT($B40&"!B$2:B$1000"),"Female") -> 30 | I40: =COUNTIF(INDIRECT($B40&"!B$2:B$1000"),"Diverse") -> 0 | J40: =H40/C40 -> 0.33707865 | K40: =COUNTIF(INDIRECT($B40&"!E$2:E$1000"),"Yes") -> 57 | L40: =K40/C40 -> 0.64044944 | M40: =COUNTIF(INDIRECT($B40&"!F$2:F$1000"),"Yes") -> 18 | N40: =M40/C40 -> 0.20224719 | O40: =COUNTIF(INDIRECT($B40&"!I$2:I$1000"),"Yes") -> 45 | P40: =O40/C40 -> 0.50561798 | Q40: 17 | R40: =Q40/E40 -> 0.28333333 | S40: 17 | T40: =S40/C40 -> 0.19101124 | U40: 11 | V40: 22 | W40: 19 | X40: =W40/C40 -> 0.21348315
...

Sheet AllParticpants
A1: ID | B1: Gender | C1: Affiliation | D1: Country of Affiliation | E1: Are you an Early Career Scientist? | F1: Do you work in industry, a Start-up or Small and Medium Enterprise? | G1: What is your scientific expertise? (Multiple Choice) | H1: Scientific expertise - Other(s): | I1: Have you used this installation before? | J1: Registration date | K1: Registration state | L1: Training | N1: Events | O1: Countries | P1: No_Countries | Q1: Category | S1: Countries | T1: No_Countries | U1: Category | X1: Country | Y1: # Registrations
A2: 37 | B2: Male | C2: IPGP | D2: France | E2: Yes | F2: No | G2: Seismology | I2: No | J2: Sep 29, 2023, 11:59 AM | K2: Completed | L2: EPOSMetadata | N2: {=UNIQUE(L2:L3120)} -> EPOSMetadata | O2: {=UNIQUE(D2:D3120)} -> France | P2: =COUNTIF(D$2:D$3120,O2) -> 131 | Q2: {=XLOOKUP(O2,Countries!A$2:A$120,Countries!B$2:B$120,"tbd",0)} -> Europe | S2: Algeria | T2: 4 | U2: Africa | X2: Africa | Y2: =SUM(T2:T12) -> 56
A3: 34 | B3: Male | C3: EMSO ERIC | D3: Italy | E3: No | F3: No | G3: Marine Sciences | I3: No | J3: Sep 29, 2023, 11:05 AM | K3: Completed | L3: EPOSMetadata | N3: ETRIS | O3: Italy | P3: =COUNTIF(D$2:D$3120,O3) -> 277 | Q3: {=XLOOKUP(O3,Countries!A$2:A$120,Countries!B$2:B$120,"tbd",0)} -> Europe | S3: Cameroon | T3: 3 | U3: Africa | X3: Asia | Y3: =SUM(T13:T25) -> 121
A4: 15 | B4: Female | C4: CNRS | D4: France | E4: Yes | F4: No | G4: Geohazard | H4: Data manager | I4: Yes | J4: Sep 28, 2023, 3:09 PM | K4: Completed | L4: EPOSMetadata | N4: HySEA_T | O4: Turkey | P4: =COUNTIF(D$2:D$3120,O4) -> 62 | Q4: {=XLOOKUP(O4,Countries!A$2:A$120,Countries!B$2:B$120,"tbd",0)} -> associated countries | S4: Congo - Kinshasa | T4: 1 | U4: Africa | X4: Middle East | Y4: 153
A5: 19 | B5: Male | C5: CNRS - OPGC | D5: France | E5: Yes | F5: No | G5: Engineering | I5: Yes | J5: Sep 28, 2023, 3:32 PM | K5: Completed | L5: EPOSMetadata | N5: FAIR1 | O5: New Zealand | P5: =COUNTIF(D$2:D$3120,O5) -> 13 | Q5: {=XLOOKUP(O5,Countries!A$2:A$120,Countries!B$2:B$120,"tbd",0)} -> associated countries | S5: Ethiopia | T5: 3 | U5: Africa | X5: Middle/South America | Y5: 90
A6: 9 | B6: Male | C6: ISTerre | D6: France | E6: Yes | F6: No | G6: Seismology | I6: No | J6: Sep 28, 2023, 1:59 PM | K6: Completed | L6: EPOSMetadata | N6: EPISODES_WS | O6: Germany | P6: =COUNTIF(D$2:D$3120,O6) -> 187 | Q6: {=XLOOKUP(O6,Countries!A$2:A$120,Countries!B$2:B$120,"tbd",0)} -> Europe | S6: Ghana | T6: 4 | U6: Africa | X6: Australia | Y6: 9
A7: 5 | B7: Female | C7: Istituto Nazionale di Geofisica e Vulcanologia | D7: Italy | E7: No | F7: No | G7: Geohazard; Tsunami | I7: Yes | J7: Sep 28, 2023, 1:27 PM | K7: Completed | L7: EPOSMetadata | N7: FAIR2 | O7: Finland | P7: =COUNTIF(D$2:D$3120,O7) -> 28 | Q7: {=XLOOKUP(O7,Countries!A$2:A$120,Countries!B$2:B$120,"tbd",0)} -> Europe | S7: Malawi | T7: 1 | U7: Africa | X7: US+Canada | Y7: =SUM(T78:T79) -> 200
A8: 70 | B8: Female | C8: Ingv | D8: Italy | E8: No | F8: No | G8: Computer Science | I8: Yes | J8: Oct 13, 2023, 5:54 PM | K8: Completed | L8: EPOSMetadata | N8: SDL_WS | O8: Romania | P8: =COUNTIF(D$2:D$3120,O8) -> 43 | Q8: {=XLOOKUP(O8,Countries!A$2:A$120,Countries!B$2:B$120,"tbd",0)} -> widening countries | S8: Morocco | T8: 25 | U8: Africa | X8: EU | Y8: 1159
A9: 12 | B9: Female | C9: Boğaziçi University- KOERI | D9: Turkey | E9: No | F9: No | G9: Seismology; Tsunami | I9: Yes | J9: Sep 28, 2023, 2:23 PM | K9: Completed | L9: EPOSMetadata | N9: ShakeMap2 | O9: Australia | P9: =COUNTIF(D$2:D$3120,O9) -> 9 | Q9: {=XLOOKUP(O9,Countries!A$2:A$120,Countries!B$2:B$120,"tbd",0)} -> Oceania | S9: Mozambique | T9: 5 | U9: Africa | X9: EU Widening Countries | Y9: 390
A10: 52 | B10: Female | C10: CINECA | D10: Italy | E10: No | F10: No | G10: Other | I10: No | J10: Oct 5, 2023, 10:25 AM | K10: Completed | L10: EPOSMetadata | N10: PyBET | O10: Switzerland | P10: =COUNTIF(D$2:D$3120,O10) -> 38 | Q10: {=XLOOKUP(O10,Countries!A$2:A$120,Countries!B$2:B$120,"tbd",0)} -> Europe | S10: Nigeria | T10: 6 | U10: Africa | X10: EU Associated Countries | Y10: =SUM(T26:T38) -> 281
A11: 80 | B11: Female | C11: WSP | D11: New Zealand | E11: Yes | F11: Yes | G11: Engineering; Seismology | I11: No | J11: Oct 16, 2023, 8:48 PM | K11: Completed | L11: EPOSMetadata | N11: SLIP | O11: United Kingdom | P11: =COUNTIF(D$2:D$3120,O11) -> 65 | Q11: {=XLOOKUP(O11,Countries!A$2:A$120,Countries!B$2:B$120,"tbd",0)} -> associated countries | S11: Uganda | T11: 3 | U11: Africa | Y11: Sum | Z11: =SUM(Y2:Y10) -> 2459
A12: 36 | B12: Female | C12: LMU - Dept. of Geophysics | D12: Germany | E12: No | F12: No | G12: Computer Science | I12: Yes | J12: Sep 29, 2023, 11:31 AM | K12: Completed | L12: EPOSMetadata | N12: FAIR3 | O12: Belgium | P12: =COUNTIF(D$2:D$3120,O12) -> 44 | Q12: {=XLOOKUP(O12,Countries!A$2:A$120,Countries!B$2:B$120,"tbd",0)} -> Europe | S12: Zimbabwe | T12: 1 | U12: Africa | V12: =SUM(T2:T12) -> 56 | Y12: EU Percentage | Z12: =SUM(Y8:Y10)/Z11 -> 0.74420496
A13: 16 | B13: Female | C13: ISPRA | D13: Italy | E13: No | F13: No | G13: Computer Science | I13: No | J13: Sep 28, 2023, 3:15 PM | K13: Completed | L13: EPOSMetadata | N13: SiteEffects | O13: Spain | P13: =COUNTIF(D$2:D$3120,O13) -> 205 | Q13: {=XLOOKUP(O13,Countries!A$2:A$120,Countries!B$2:B$120,"tbd",0)} -> Europe | S13: China | T13: 30 | U13: Asia
A14: 73 | B14: Male | C14: University of Helsinki | D14: Finland | E14: No | F14: No | G14: Computer Science; Engineering; Seismology | H14: Seismic ambient noise | I14: No | J14: Oct 16, 2023, 10:36 AM | K14: Completed | L14: EPOSMetadata | N14: HPS1 | O14: Iceland | P14: =COUNTIF(D$2:D$3120,O14) -> 34 | Q14: {=XLOOKUP(O14,Countries!A$2:A$120,Countries!B$2:B$120,"tbd",0)} -> associated countries | S14: Hongkong | T14: 3 | U14: Asia
A15: 79 | B15: Female | C15: National Institute for Earth Physics | D15: Romania | E15: No | F15: No | G15: Seismology | I15: Yes | J15: Oct 16, 2023, 3:53 PM | K15: Completed | L15: EPOSMetadata | N15: FAIR4 | O15: Greece | P15: =COUNTIF(D$2:D$3120,O15) -> 86 | Q15: {=XLOOKUP(O15,Countries!A$2:A$120,Countries!B$2:B$120,"tbd",0)} -> widening countries | S15: Indonesia | T15: 31 | U15: Asia
A16: 28 | B16: Female | C16: National Computational Infrastructure | D16: Australia | E16: No | F16: No | G16: Other | H16: Metadata, repository administration | I16: No | J16: Sep 29, 2023, 12:19 AM | K16: Completed | L16: EPOSMetadata | N16: FAIR5 | O16: Norway | P16: =COUNTIF(D$2:D$3120,O16) -> 41 | Q16: {=XLOOKUP(O16,Countries!A$2:A$120,Countries!B$2:B$120,"tbd",0)} -> associated countries | S16: Japan | T16: 14 | U16: Asia
A17: 17 | B17: Male | C17: ETH Zurich | D17: Switzerland | E17: No | F17: No | G17: Geohazard; Seismology | I17: Yes | J17: Sep 28, 2023, 3:18 PM | K17: Completed | L17: EPOSMetadata | N17: SLSMF | O17: Croatia | P17: =COUNTIF(D$2:D$3120,O17) -> 23 | Q17: {=XLOOKUP(O17,Countries!A$2:A$120,Countries!B$2:B$120,"tbd",0)} -> widening countries | S17: Kyrgyzstan | T17: 1 | U17: Asia
A18: 55 | B18: Female | C18: EPOS ERIC | D18: Italy | E18: No | F18: No | G18: Energy Transformation/Storage; Engineering | I18: No | J18: Oct 7, 2023, 11:52 PM | K18: Completed | L18: EPOSMetadata | N18: HySEA_L | O18: Poland | P18: =COUNTIF(D$2:D$3120,O18) -> 69 | Q18: {=XLOOKUP(O18,Countries!A$2:A$120,Countries!B$2:B$120,"tbd",0)} -> widening countries | S18: Malaysia | T18: 2 | U18: Asia
A19: 38 | B19: Female | C19: British Geological Survey/University of Edinburgh | D19: United Kingdom | E19: Yes | F19: No | G19: Computer Science; Engineering | I19: No | J19: Sep 29, 2023, 3:31 PM | K19: Completed | L19: EPOSMetadata | N19: FAIR6 | O19: Portugal | P19: =COUNTIF(D$2:D$3120,O19) -> 109 | Q19: {=XLOOKUP(O19,Countries!A$2:A$120,Countries!B$2:B$120,"tbd",0)} -> widening countries | S19: Maldives | T19: 1 | U19: Asia
A20: 4 | B20: Diverse | C20: GFZ Potsdam | D20: Germany | E20: No | F20: No | G20: Engineering; Seismology | I20: No | J20: Sep 28, 2023, 1:09 PM | K20: Completed | L20: EPOSMetadata | N20: EPOS_3 | O20: Bulgaria | P20: =COUNTIF(D$2:D$3120,O20) -> 12 | Q20: {=XLOOKUP(O20,Countries!A$2:A$120,Countries!B$2:B$120,"tbd",0)} -> widening countries | S20: Philippines | T20: 10 | U20: Asia
A21: 48 | B21: Male | C21: ROB | D21: Belgium | E21: No | F21: No | G21: Computer Science; Solid Earth | I21: Yes | J21: Oct 4, 2023, 9:54 AM | K21: Completed | L21: EPOSMetadata | N21: EPISODES_Trg | O21: Iran | P21: =COUNTIF(D$2:D$3120,O21) -> 57 | Q21: {=XLOOKUP(O21,Countries!A$2:A$120,Countries!B$2:B$120,"tbd",0)} -> Middle East | S21: Singapore | T21: 10 | U21: Asia
A22: 13 | B22: Male | C22: CSIC | D22: Spain | E22: No | F22: No | G22: Atmospheric Physics; Computer Science; Geohazard; Solid Earth; Volcanology | I22: Yes | J22: Sep 28, 2023, 2:58 PM | K22: Completed | L22: EPOSMetadata | N22: FAIR7 | O22: Netherlands | P22: =COUNTIF(D$2:D$3120,O22) -> 10 | Q22: {=XLOOKUP(O22,Countries!A$2:A$120,Countries!B$2:B$120,"tbd",0)} -> Europe | S22: South Korea | T22: 4 | U22: Asia
A23: 45 | B23: Female | C23: Icelandic Meteorological Office | D23: Iceland | E23: Yes | F23: No | G23: Solid Earth; Volcanology | H23: geodesy | I23: Yes | J23: Oct 3, 2023, 3:09 PM | K23: Completed | L23: EPOSMetadata | N23: ORFEUS_unique | O23: Taiwan | P23: =COUNTIF(D$2:D$3120,O23) -> 10 | Q23: {=XLOOKUP(O23,Countries!A$2:A$120,Countries!B$2:B$120,"tbd",0)} -> Asia | S23: Taiwan | T23: 10 | U23: Asia
A24: 88 | B24: Female | C24: ISPRA | D24: Italy | E24: Yes | F24: Yes | G24: Environmental Protection; Geohazard | I24: No | J24: Oct 19, 2023, 10:05 AM | K24: Completed | L24: EPOSMetadata | N24: Quakeworx | O24: Canada | P24: =COUNTIF(D$2:D$3120,O24) -> 14 | Q24: {=XLOOKUP(O24,Countries!A$2:A$120,Countries!B$2:B$120,"tbd",0)} -> U.S. + Canada | S24: United Arab Emirates | T24: 2 | U24: Asia
A25: 67 | B25: Male | C25: Aristotle University of Thessaloniki - Dpt of Geophysics | D25: Greece | E25: No | F25: No | G25: Seismology | I25: Yes | J25: Oct 13, 2023, 12:50 PM | K25: Completed | L25: EPOSMetadata | N25: Hackathon1 | O25: United States | P25: =COUNTIF(D$2:D$3120,O25) -> 186 | Q25: {=XLOOKUP(O25,Countries!A$2:A$120,Countries!B$2:B$120,"tbd",0)} -> U.S. + Canada | S25: Vietnam | T25: 3 | U25: Asia | V25: =SUM(T13:T25) -> 121
A26: 58 | B26: Female | C26: National Institute for Earth Physics | D26: Romania | E26: No | F26: No | G26: Atmospheric Physics; Seismology | I26: Yes | J26: Oct 10, 2023, 2:01 PM | K26: Completed | L26: EPOSMetadata | N26: EPOS_Trg_CZ | O26: Japan | P26: =COUNTIF(D$2:D$3120,O26) -> 14 | Q26: {=XLOOKUP(O26,Countries!A$2:A$120,Countries!B$2:B$120,"tbd",0)} -> Asia | S26: Albania | T26: 24 | U26: associated countries
A27: 32 | B27: Male | C27: University of Grenoble Alpes | D27: France | E27: Yes | F27: No | G27: Engineering; Geohazard; Seismology | I27: No | J27: Sep 29, 2023, 10:48 AM | K27: Completed | L27: EPOSMetadata | N27: EPOS_Trg_Spain | O27: Malta | P27: =COUNTIF(D$2:D$3120,O27) -> 3 | Q27: {=XLOOKUP(O27,Countries!A$2:A$120,Countries!B$2:B$120,"tbd",0)} -> widening countries | S27: Bosnia and Herzegovina | T27: 3 | U27: associated countries
A28: 56 | B28: Female | C28: NORSAR | D28: Norway | E28: Yes | F28: No | G28: Geohazard; Seismology | I28: Yes | J28: Oct 9, 2023, 3:36 PM | K28: Completed | L28: EPOSMetadata | N28: EPOS_SummerSchool | O28: Bangladesh | P28: =COUNTIF(D$2:D$3120,O28) -> 3 | Q28: {=XLOOKUP(O28,Countries!A$2:A$120,Countries!B$2:B$120,"tbd",0)} -> Middle East | S28: Iceland | T28: 34 | U28: associated countries
A29: 49 | B29: Male | C29: Universidad de Málaga | D29: Spain | E29: No | F29: No | G29: Computer Science; Geohazard; Tsunami | I29: No | J29: Oct 4, 2023, 5:41 PM | K29: Completed | L29: EPOSMetadata | N29: EPOSTrg_S4E | O29: Pakistan | P29: =COUNTIF(D$2:D$3120,O29) -> 13 | Q29: {=XLOOKUP(O29,Countries!A$2:A$120,Countries!B$2:B$120,"tbd",0)} -> Middle East | S29: Israel | T29: 7 | U29: associated countries
A30: 23 | B30: Female | C30: Geosciences Barcelona- CSIC | D30: Spain | E30: Yes | F30: No | G30: Atmospheric Physics; Computer Science; Geohazard; Volcanology | I30: No | J30: Sep 28, 2023, 3:59 PM | K30: Completed | L30: EPOSMetadata | N30: EPOSTrg_France | O30: India | P30: =COUNTIF(D$2:D$3120,O30) -> 49 | Q30: {=XLOOKUP(O30,Countries!A$2:A$120,Countries!B$2:B$120,"tbd",0)} -> Middle East | S30: Montenegro | T30: 6 | U30: associated countries
A31: 7 | B31: Female | C31: University of Helsinki | D31: Finland | E31: No | F31: No | G31: Atmospheric Physics | H31: Research infrastructure coordination | I31: Yes | J31: Sep 28, 2023, 1:53 PM | K31: Completed | L31: EPOSMetadata | N31: EPOSTrg_EGU25 | O31: Egypt | P31: =COUNTIF(D$2:D$3120,O31) -> 13 | Q31: {=XLOOKUP(O31,Countries!A$2:A$120,Countries!B$2:B$120,"tbd",0)} -> Middle East | S31: New Zealand | T31: 13 | U31: associated countries
A32: 46 | B32: Male | C32: National Computational Infrastructure | D32: Australia | E32: Yes | F32: Yes | G32: Computer Science; Seismology | H32: Glaciology | I32: No | J32: Oct 3, 2023, 4:03 PM | K32: Completed | L32: EPOSMetadata | N32: EPOSTrg_Online25 | O32: Nepal | P32: =COUNTIF(D$2:D$3120,O32) -> 4 | Q32: {=XLOOKUP(O32,Countries!A$2:A$120,Countries!B$2:B$120,"tbd",0)} -> Middle East | S32: North Macedonia | T32: 17 | U32: associated countries
A33: 30 | B33: Male | C33: Federal Institute for Geosciences and Natural Resources (BGR) | D33: Germany | E33: Yes | F33: No | G33: Atmospheric Physics | H33: infrasound | I33: Yes | J33: Sep 29, 2023, 9:27 AM | K33: Completed | L33: EPOSMetadata | N33: VIS_WS | O33: Albania | P33: =COUNTIF(D$2:D$3120,O33) -> 24 | Q33: {=XLOOKUP(O33,Countries!A$2:A$120,Countries!B$2:B$120,"tbd",0)} -> associated countries | S33: Norway | T33: 41 | U33: associated countries
A34: 31 | B34: Male | C34: Università degli Studi di Firenze | D34: Italy | E34: Yes | F34: No | G34: Atmospheric Physics; Computer Science; Geohazard; Seismology; Solid Earth; Tsunami; Volcanology | I34: No | J34: Sep 29, 2023, 10:40 AM | K34: Completed | L34: EPOSMetadata | N34: SDL_Trg | O34: Singapore | P34: =COUNTIF(D$2:D$3120,O34) -> 10 | Q34: {=XLOOKUP(O34,Countries!A$2:A$120,Countries!B$2:B$120,"tbd",0)} -> Asia | S34: Serbia | T34: 4 | U34: associated countries
A35: 76 | B35: Diverse | C35: GFZ Potsdam | D35: Germany | E35: Yes | F35: Yes | G35: Computer Science; Seismology; Solid Earth | I35: Yes | J35: Oct 16, 2023, 1:22 PM | K35: Completed | L35: EPOSMetadata | N35: Geohazard_WS1 | O35: Mexico | P35: =COUNTIF(D$2:D$3120,O35) -> 11 | Q35: {=XLOOKUP(O35,Countries!A$2:A$120,Countries!B$2:B$120,"tbd",0)} -> Middle/South America | S35: Tunisia | T35: 1 | U35: associated countries
A36: 2 | B36: Male | C36: GFZ | D36: Germany | E36: Yes | F36: No | G36: Computer Science; Engineering; Geohazard; Seismology | I36: No | J36: Sep 28, 2023, 1:00 PM | K36: Completed | L36: EPOSMetadata | O36: Peru | P36: =COUNTIF(D$2:D$3120,O36) -> 5 | Q36: {=XLOOKUP(O36,Countries!A$2:A$120,Countries!B$2:B$120,"tbd",0)} -> Middle/South America | S36: Turkey | T36: 62 | U36: associated countries
A37: 72 | B37: Female | C37: Seismologist | D37: Croatia | E37: No | F37: No | G37: Seismology; Solid Earth | I37: No | J37: Oct 15, 2023, 9:49 PM | K37: Completed | L37: EPOSMetadata | O37: China | P37: =COUNTIF(D$2:D$3120,O37) -> 30 | Q37: {=XLOOKUP(O37,Countries!A$2:A$120,Countries!B$2:B$120,"tbd",0)} -> Asia | S37: Ukraine | T37: 4 | U37: associated countries
A38: 6 | B38: Female | C38: University of Potsdam | D38: Germany | E38: Yes | F38: No | G38: Seismology | I38: No | J38: Sep 28, 2023, 1:47 PM | K38: Completed | L38: EPOSMetadata | O38: Tunisia | P38: =COUNTIF(D$2:D$3120,O38) -> 1 | Q38: {=XLOOKUP(O38,Countries!A$2:A$120,Countries!B$2:B$120,"tbd",0)} -> associated countries | S38: United Kingdom | T38: 65 | U38: associated countries | V38: =SUM(T26:T38) -> 281
A39: 21 | B39: Male | C39: DT-GEO / UKRI-BGS | D39: United Kingdom | E39: No | F39: No | G39: Computer Science | I39: Yes | J39: Sep 28, 2023, 3:52 PM | K39: Completed | L39: EPOSMetadata | O39: Philippines | P39: =COUNTIF(D$2:D$3120,O39) -> 10 | Q39: {=XLOOKUP(O39,Countries!A$2:A$120,Countries!B$2:B$120,"tbd",0)} -> Asia | S39: Andorra | T39: 2 | U39: Europe
A40: 86 | B40: Male | C40: National and Kapodistrian University of Athens | D40: Greece | E40: Yes | F40: No | G40: Seismology | I40: Yes | J40: Oct 18, 2023, 8:50 PM | K40: Completed | L40: EPOSMetadata | O40: Malaysia | P40: =COUNTIF(D$2:D$3120,O40) -> 2 | Q40: {=XLOOKUP(O40,Countries!A$2:A$120,Countries!B$2:B$120,"tbd",0)} -> Asia | S40: Austria | T40: 12 | U40: Europe
...

Sheet ISCPoster_Data
A1: Date | B1: Training_Name | C1: # Registrations | D1: m+f+d | E1: # Participants | F1: Attend_Rate | G1: Male | H1: Female | I1: Diverse | J1: Female % | K1: ECS | L1: ECS % | M1: SME | N1: SME % | O1: Familar? | P1: Familiar? % | Q1: FeedbackF | R1: FeedbackF % | S1: wideningC | T1: wideningC % | U1: #Scientific fields | V1: #Countries | W1: non-EU | X1: non-EU % | Y1: America
A2: Summary | B2: 4 EPOS Trg | C2: 663 | D2: 625 | E2: 402 | F2: 0.60633484 | G2: 287 | H2: 336 | I2: 2 | J2: 0.50678733 | K2: 77 | L2: 0.11613876 | M2: 20 | N2: 0.11123314 | O2: 71 | P2: 0.10708899
B3: .
A4: 45047 | B4: HPS-SCOPED1 | C4: 205 | D4: 205 | E4: 134 | F4: 0.65365854 | G4: 128 | H4: 70 | I4: 7 | J4: 0.34146341 | K4: 84 | L4: 0.4097561 | M4: 15 | N4: 0.073170732 | O4: 186 | P4: 0.90731707 | S4: 10 | T4: 0.048780488 | U4: 4 | V4: 33 | W4: 113 | X4: 0.55121951 | Y4: 90
A5: 45231 | B5: ETRiS | C5: 234 | D5: 234 | E5: 144 | F5: 0.61538462 | G5: 145 | H5: 89 | I5: 0 | J5: 0.38034188 | K5: 171 | L5: 0.73076923 | M5: 67 | N5: 0.28632479 | O5: 3 | P5: 0.012820513 | Q5: 28 | R5: 0.19444444 | S5: 20 | T5: 0.085470085 | U5: 27 | V5: 46 | W5: 109 | X5: 0.46581197
A6: 45383 | B6: HySEA_T | C6: 66 | D6: 66 | E6: 57 | F6: 0.86363636 | G6: 37 | H6: 27 | I6: 2 | J6: 0.40909091 | K6: 46 | L6: 0.6969697 | M6: 7 | N6: 0.10606061 | O6: 16 | P6: 0.24242424 | Q6: 20 | R6: 0.3030303 | S6: 3 | T6: 0.045454545 | U6: 15 | V6: 19 | W6: 31 | X6: 0.46969697
A7: 45754 | B7: HySEA_L | C7: 105 | D7: 105 | E7: 79 | F7: 0.75238095 | G7: 64 | H7: 40 | I7: 1 | J7: 0.38095238 | K7: 74 | L7: 0.7047619 | M7: 14 | N7: 0.13333333 | P7: 0 | R7: 0 | S7: 21 | T7: 0.2 | U7: 12 | V7: 28 | W7: 48 | X7: 0.45714286
A8: 45536 | B8: PyBET | C8: 18 | D8: 18 | E8: 18 | F8: 1 | G8: 13 | H8: 5 | I8: 0 | J8: 0.27777778 | K8: 13 | L8: 0.72222222 | M8: 1 | N8: 0.055555556 | O8: 2 | P8: 0.11111111 | Q8: 5 | R8: 0.27777778 | S8: 2 | T8: 0.11111111 | U8: 8 | V8: 11 | W8: 11 | X8: 0.61111111 | Z8: preliminary results from feedback, survey still open
A9: 45536 | B9: SDL_WS | C9: 130 | D9: 126 | E9: 126 | F9: 0.96923077 | G9: 73 | H9: 53 | I9: 0 | J9: 0.40769231 | K9: 61 | L9: 0.46923077 | M9: 8 | N9: 0.061538462 | O9: 23 | P9: 0.17692308 | Q9: 21 | R9: 0.16666667 | S9: 4 | T9: 0.030769231 | U9: 12 | V9: 26 | W9: 42 | X9: 0.32307692 | Z9: preliminary results from feedback, survey still open
A10: January 2025 | B10: Quakeworx | C10: 149 | D10: 148 | E10: 81 | F10: 0.54362416 | G10: 101 | H10: 44 | I10: 3 | J10: 0.29530201 | K10: 0 | L10: 0 | M10: 1 | N10: 0.0067114094 | O10: 14 | P10: 0.093959732 | R10: 0 | T10: 0 | X10: 0
A11: Summary | B11: 7 HPC Events | C11: 907 | D11: 902 | E11: 639 | F11: 0.7045204 | G11: 561 | H11: 328 | I11: 13 | J11: 0.36163175 | K11: 449 | L11: 0.49503859 | M11: 113 | N11: 0.12458655
B12: .
A13: Summary | B13: 7 FAIR Trg | C13: 379 | D13: 379 | E13: 271 | F13: 0.71503958 | G13: 162 | H13: 214 | I13: 3 | J13: 0.5646438 | K13: 142 | L13: 0.37467018 | M13: 27 | N13: 0.071240106 | O13: 274 | P13: 0.72295515
B14: .
A15: Summary | B15: 5 Portal Trg | C15: 274 | D15: 274 | E15: 187 | F15: 0.68248175 | G15: 174 | H15: 98 | I15: 2 | J15: 0.35766423 | K15: 152 | L15: 0.55474453 | M15: 53 | N15: 0.19343066 | O15: 135 | P15: 0.49270073
B16: .
A17: Summary | B17: 2 ShakeMapWS | C17: 114 | D17: 112 | E17: 108 | F17: 0.94736842 | G17: 59 | H17: 53 | I17: 0 | J17: 0.46491228 | K17: 15 | L17: 0.2027027 | M17: 2 | N17: 0.01754386 | O17: 0 | P17: 0
B18: .
A19: Summary | B19: 7 ORFEUS Trg | C19: 585 | D19: 585 | E19: 431 | F19: 0.73675214 | G19: 312 | H19: 256 | I19: 17 | J19: 0.43760684 | K19: 198 | L19: 2.6631312 | M19: 32 | N19: 0.054700855 | O19: 373 | P19: 0.63760684
B20: .
A21: Summary | B21: 3 Schools | C21: 171 | D21: 170 | E21: 170 | F21: 1 | G21: 121 | H21: 47 | I21: 2 | J21: 0.37288997 | K21: 98 | L21: 0.57309942 | M21: 6 | N21: 0.27272727
B23: Sum | C23: =SUM(C2:C21)-C11 -> 3093 | D23: =SUM(D2:D21)-D11 -> 3047 | E23: =SUM(E2:E21)-E11 -> 2208 | F23: =E23/C23 -> 0.71387003 | G23: =SUM(G2:G21)-G11 -> 1676 | H23: =SUM(H2:H21)-H11 -> 1332 | I23: =SUM(I2:I21)-I11 -> 39 | J23: =H23/C23 -> 0.43064985 | K23: =SUM(K2:K21)-K11 -> 1131 | L23: =K23/C23 -> 0.3656644 | M23: =SUM(M2:M21)-M11 -> 253 | N23: =M23/C23 -> 0.081797607 | O23: =SUM(O2:O21)-O11 -> 1097 | P23: =O23/C23 -> 0.35467184
B24: Sum (wrong) | C24: 2524.5 | D24: 2480 | E24: 1759 | F24: 0.69677164 | G24: 1335.5 | H24: 1123.5 | I24: 21 | J24: 0.44503862 | K24: 954 | L24: 0.37789661 | M24: 228 | N24: 0.090314914 | O24: 951 | P24: 0.37670826 | Q24: 471 | R24: 0.26776578 | S24: 515 | T24: 0.20400079 | W24: 519 | X24: 0.20558526

Sheet ORFEUS_allParticipants
A1: id | B1: Gender | C1: Affiliation | D1: Country of Affiliation | E1: ECS | F1: Do you primarily work in the private sector? | G1: What is your background? | H1: Please choose the role / career stage that best applies to you: | I1: Have you been familiar with the FAIR principles before? | J1: Registration date | K1: How did you hear about this event: | L1: Tags
A2: 236 | B2: Male | C2: Institute of Geosciences | D2: Albania | E2: Yes | F2: No | G2: Seismology | H2: Scientists | L2: ORFEUS_unique
A3: 45 | B3: Female | C3: Institute of Geosciences | D3: Albania | E3: Yes | F3: No | G3: Computer sciences | H3: Senior Scientist | L3: ORFEUS_unique
A4: 76 | B4: Female | C4: Institute of Geosciences, Tirana | D4: Albania | E4: No | F4: No | G4: Seismology | H4: PhD Candidate | L4: ORFEUS_unique
A5: 103 | B5: Male | C5: IGEO | D5: Albania | E5: Yes | F5: No | G5: Seismology, Engineering seismology / soil dynamics and earthquake engineering, Environmental protection | H5: Technician | L5: ORFEUS_unique
A6: 148 | B6: Male | C6: Institute of Geosciences | D6: Albania | E6: Yes | F6: No | G6: Seismology | H6: PhD Candidate | L6: ORFEUS_unique
A7: 232 | B7: Male | C7: Institute of Geoscience | D7: Albania | E7: Yes | F7: No | G7: Seismology, Computer sciences | H7: PhD Candidate | L7: ORFEUS_unique
A8: 275 | B8: Female | C8: Institute of Geosciences | D8: Albania | E8: No | F8: No | G8: Engineering seismology / soil dynamics and earthquake engineering, Other Earth science field | H8: Scientists | L8: ORFEUS_unique
A9: 114 | B9: Male | C9: GeoSphere Austria | D9: Austria | E9: No | F9: No | G9: Seismology | H9: Technician | L9: ORFEUS_unique
A10: 209 | B10: Female | C10: GeoSphere Austria | D10: Austria | E10: Yes | F10: No | G10: Seismology, Landslides, Atmospheric physics | H10: PhD Candidate | L10: ORFEUS_unique
A11: 267 | B11: Female | C11: GeoSphere Austria | D11: Austria | E11: Yes | F11: Yes | G11: Seismology | H11: Other | L11: ORFEUS_unique
A12: 82 | B12: Male | C12: ROB | D12: Belgium | E12: No | F12: No | G12: GNSS, Computer sciences | H12: Scientists | L12: ORFEUS_unique
A13: 101 | B13: Male | C13: Royal Observatory of Belgium | D13: Belgium | E13: No | F13: No | G13: Computer sciences | H13: Technician | L13: ORFEUS_unique
... A316: 137 | B316: Male | C316: Addis Ababa University | D316: Ethiopia | E316: Yes | F316: No | G316: Seismology | H316: Scientists | L316: ORFEUS_unique

Sheet WP5Participants
A1: ID | B1: Gender | C1: Affiliation | D1: Country of Affiliation | E1: Are you an Early Career Scientist? | F1: Do you work in industry, a Start-up or Small and Medium Enterprise? | G1: What is your scientific expertise? (Multiple Choice) | H1: Scientific expertise - Other(s): | I1: Have you used this installation (EPOS) before? | J1: Registration date | K1: Registration state | L1: Training | O1: Countries | P1: No_Countries | Q1: Category | X1: Country | Y1: # Registrations
A2: 13 | B2: Female | C2: University of Trieste | D2: Italy | E2: Yes | F2: No | G2: Tsunami | I2: Yes | J2: Apr 5, 2024, 12:39 AM | K2: Completed | L2: HySEA | O2: {=UNIQUE(D2:D600)} -> Italy | P2: =COUNTIF(D$2:D$600,O2) -> 69 | Q2: {=XLOOKUP(O2,Countries!A$2:A$98,Countries!B$2:B$98,"tbd",0)} -> Europe
A3: 55 | B3: Female | C3: LMU | D3: Germany | E3: Yes | F3: No | G3: Seismology | I3: No | J3: Apr 16, 2024, 3:08 PM | K3: Completed | L3: HySEA | O3: Germany | P3: =COUNTIF(D$2:D$600,O3) -> 62 | Q3: {=XLOOKUP(O3,Countries!A$2:A$98,Countries!B$2:B$98,"tbd",0)} -> Europe
A4: 52 | B4: Male | C4: Shoa | D4: Chile | E4: Yes | F4: No | G4: Seismology; Tsunami | I4: No | J4: Apr 12, 2024, 12:27 AM | K4: Completed | L4: HySEA | O4: Chile | P4: =COUNTIF(D$2:D$600,O4) -> 15 | Q4: {=XLOOKUP(O4,Countries!A$2:A$98,Countries!B$2:B$98,"tbd",0)} -> Middle/South America
A5: 19 | B5: Female | C5: Post-Doc | D5: Italy | E5: Yes | F5: No | G5: Seismology; Tsunami | I5: Yes | J5: Apr 5, 2024, 2:33 PM | K5: Completed | L5: HySEA | O5: France | P5: =COUNTIF(D$2:D$600,O5) -> 22 | Q5: {=XLOOKUP(O5,Countries!A$2:A$98,Countries!B$2:B$98,"tbd",0)} -> Europe
A6: 56 | B6: Male | C6: Université Côte d'Azur, Universidad de Alcalá | D6: France | E6: Yes | F6: No | G6: Energy Transformation/Storage; Engineering; Marine Sciences | H6: ocean-bottom instrumentation | I6: No | J6: Apr 20, 2024, 2:55 PM | K6: Completed | L6: HySEA | O6: Turkey | P6: =COUNTIF(D$2:D$600,O6) -> 11 | Q6: {=XLOOKUP(O6,Countries!A$2:A$98,Countries!B$2:B$98,"tbd",0)} -> associated countries
A7: 11 | B7: Female | C7: Engineer | D7: Chile | E7: Yes | F7: Yes | G7: Engineering; Marine Sciences; Tsunami | I7: Yes | J7: Apr 4, 2024, 11:40 PM | K7: Completed | L7: HySEA | O7: Greece | P7: =COUNTIF(D$2:D$600,O7) -> 14 | Q7: {=XLOOKUP(O7,Countries!A$2:A$98,Countries!B$2:B$98,"tbd",0)} -> widening countries
A8: 15 | B8: Female | C8: Bogazici University | D8: Turkey | E8: No | F8: No | G8: Seismology | I8: Yes | J8: Apr 5, 2024, 6:29 AM | K8: Completed | L8: HySEA | O8: Israel | P8: =COUNTIF(D$2:D$600,O8) -> 3 | Q8: {=XLOOKUP(O8,Countries!A$2:A$98,Countries!B$2:B$98,"tbd",0)} -> associated countries
A9: 20 | B9: Female | C9: INGV | D9: Italy | E9: Yes | F9: No | G9: Seismology; Tsunami | I9: No | J9: Apr 5, 2024, 2:34 PM | K9: Completed | L9: HySEA | O9: Spain | P9: =COUNTIF(D$2:D$600,O9) -> 42 | Q9: {=XLOOKUP(O9,Countries!A$2:A$98,Countries!B$2:B$98,"tbd",0)} -> Europe
A10: 3 | B10: Male | C10: n/a | D10: Greece | E10: Yes | F10: No | G10: Geohazard; Seismology; Solid Earth | I10: No | J10: Mar 21, 2024, 11:12 AM | K10: Completed | L10: HySEA | O10: Ecuador | P10: =COUNTIF(D$2:D$600,O10) -> 5 | Q10: {=XLOOKUP(O10,Countries!A$2:A$98,Countries!B$2:B$98,"tbd",0)} -> Middle/South America
A11: 1 | B11: Female | C11: LMU - Dept. of Geophysics | D11: Germany | E11: No | F11: No | G11: Computer Science | I11: No | J11: Mar 20, 2024, 9:21 AM | K11: Completed | L11: HySEA | O11: Indonesia | P11: =COUNTIF(D$2:D$600,O11) -> 9 | Q11: {=XLOOKUP(O11,Countries!A$2:A$98,Countries!B$2:B$98,"tbd",0)} -> Asia
A12: 45 | B12: Male | C12: None | D12: Chile | E12: Yes | F12: Yes | G12: Engineering; Seismology | I12: No | J12: Apr 8, 2024, 5:50 PM | K12: Completed | L12: HySEA | O12: Pakistan | P12: =COUNTIF(D$2:D$600,O12) -> 4 | Q12: {=XLOOKUP(O12,Countries!A$2:A$98,Countries!B$2:B$98,"tbd",0)} -> Middle East
A13: 39 | B13: Male | C13: Istituto Nazionale di Oceanografia e Geofisica Sperimentale (OGS) | D13: Italy | E13: Yes | F13: No | G13: Seismology | H13: Earthquake and Tsunami Hazard Assessment | I13: No | J13: Apr 6, 2024, 8:55 PM | K13: Completed | L13: HySEA | O13: Peru | P13: =COUNTIF(D$2:D$600,O13) -> 1 | Q13: {=XLOOKUP(O13,Countries!A$2:A$98,Countries!B$2:B$98,"tbd",0)} -> Middle/South America
A14: 7 | B14: Male | C14: Geological survey of israel | D14: Israel | E14: Yes | F14: No | G14: Engineering; Geohazard; Seismology; Tsunami | I14: No | J14: Mar 31, 2024, 12:38 PM | K14: Completed | L14: HySEA | O14: Iran | P14: =COUNTIF(D$2:D$600,O14) -> 13 | Q14: {=XLOOKUP(O14,Countries!A$2:A$98,Countries!B$2:B$98,"tbd",0)} -> Middle East
A15: 22 | B15: Female | C15: Instituto Geográfico Nacional | D15: Spain | E15: No | F15: No | G15: Seismology | I15: Yes | J15: Apr 5, 2024, 2:52 PM | K15: Completed | L15: HySEA | O15: Austria | P15: =COUNTIF(D$2:D$600,O15) -> 4 | Q15: {=XLOOKUP(O15,Countries!A$2:A$98,Countries!B$2:B$98,"tbd",0)} -> Europe
A16: 60 | B16: Male | C16: IH Cantabria | D16: Spain | E16: Yes | F16: No | G16: Marine Sciences; Tsunami | I16: Yes | J16: Apr 22, 2024, 3:23 PM | K16: Completed | L16: HySEA | O16: Romania | P16: =COUNTIF(D$2:D$600,O16) -> 7 | Q16: {=XLOOKUP(O16,Countries!A$2:A$98,Countries!B$2:B$98,"tbd",0)} -> widening countries
A17: 66 | B17: Male | C17: IHCantabria | D17: Spain | E17: Yes | F17: Yes | G17: Engineering; Marine Sciences | H17: Beach morphodynamics | I17: No | J17: Apr 24, 2024, 10:50 AM | K17: Completed | L17: HySEA | O17: United States | P17: =COUNTIF(D$2:D$600,O17) -> 106 | Q17: {=XLOOKUP(O17,Countries!A$2:A$98,Countries!B$2:B$98,"tbd",0)} -> U.S. + Canada
A18: 25 | B18: Diverse | C18: GFZ | D18: Germany | E18: Yes | F18: No | G18: Engineering; Geohazard; Seismology | I18: No | J18: Apr 5, 2024, 3:40 PM | K18: Completed | L18: HySEA | O18: Belgium | P18: =COUNTIF(D$2:D$600,O18) -> 1 | Q18: {=XLOOKUP(O18,Countries!A$2:A$98,Countries!B$2:B$98,"tbd",0)} -> Europe
A19: 32 | B19: Male | C19: Universidad Andres Bello | D19: Chile | E19: Yes | F19: No | G19: Computer Science; Geohazard; Marine Sciences; Seismology; Solid Earth; Tsunami; Volcanology | I19: No | J19: Apr 6, 2024, 12:44 AM | K19: Completed | L19: HySEA | O19: United Kingdom | P19: =COUNTIF(D$2:D$600,O19) -> 7 | Q19: {=XLOOKUP(O19,Countries!A$2:A$98,Countries!B$2:B$98,"tbd",0)} -> associated countries
A20: 30 | B20: Male | C20: ESPOL | D20: Ecuador | E20: Yes | F20: No | G20: Computer Science; Engineering; Geohazard; Marine Sciences; Tsunami; Volcanology | H20: ocean engineering | I20: No | J20: Apr 5, 2024, 9:33 PM | K20: Completed | L20: HySEA | O20: Taiwan | P20: =COUNTIF(D$2:D$600,O20) -> 5 | Q20: {=XLOOKUP(O20,Countries!A$2:A$98,Countries!B$2:B$98,"tbd",0)} -> Asia
A21: 64 | B21: Diverse | C21: UMA | D21: Spain | E21: Yes | F21: No | G21: Tsunami | I21: Yes | J21: Apr 23, 2024, 4:00 PM | K21: Completed | L21: HySEA | O21: Switzerland | P21: =COUNTIF(D$2:D$600,O21) -> 13 | Q21: {=XLOOKUP(O21,Countries!A$2:A$98,Countries!B$2:B$98,"tbd",0)} -> Europe
A22: 46 | B22: Female | C22: Cigiden | D22: Chile | E22: Yes | F22: No | G22: Tsunami | I22: Yes | J22: Apr 8, 2024, 9:25 PM | K22: Completed | L22: HySEA | O22: Iceland | P22: =COUNTIF(D$2:D$600,O22) -> 5 | Q22: {=XLOOKUP(O22,Countries!A$2:A$98,Countries!B$2:B$98,"tbd",0)} -> associated countries
A23: 54 | B23: Male | C23: Pontificia Universidad Católica de Valparaíso | D23: Chile | E23: Yes | F23: No | G23: Geohazard; Tsunami | I23: No | J23: Apr 15, 2024, 5:43 PM | K23: Completed | L23: HySEA | O23: China | P23: =COUNTIF(D$2:D$600,O23) -> 10 | Q23: {=XLOOKUP(O23,Countries!A$2:A$98,Countries!B$2:B$98,"tbd",0)} -> Asia
A24: 28 | B24: Female | C24: Escuela Superior Politécnica del Litoral | D24: Ecuador | E24: Yes | F24: No | G24: Environmental Protection; Engineering; Marine Sciences; Tsunami | I24: No | J24: Apr 5, 2024, 7:54 PM | K24: Completed | L24: HySEA | O24: South Korea | P24: =COUNTIF(D$2:D$600,O24) -> 3 | Q24: {=XLOOKUP(O24,Countries!A$2:A$98,Countries!B$2:B$98,"tbd",0)} -> Asia
A25: 57 | B25: Male | C25: Meteorology, Climatology and Geophysics Agency of Indonesia | D25: Indonesia | E25: Yes | F25: No | G25: Computer Science; Geohazard; Seismology; Tsunami | I25: No | J25: Apr 22, 2024, 3:10 AM | K25: Completed | L25: HySEA | O25: Saudi Arabia | P25: =COUNTIF(D$2:D$600,O25) -> 9 | Q25: {=XLOOKUP(O25,Countries!A$2:A$98,Countries!B$2:B$98,"tbd",0)} -> Middle East
A26: 59 | B26: Male | C26: NED University of Engineering and Technology | D26: Pakistan | E26: No | F26: No | G26: Engineering; Tsunami | H26: Mathematics and coastal engineering | I26: No | J26: Apr 22, 2024, 6:46 AM | K26: Completed | L26: HySEA | O26: Japan | P26: =COUNTIF(D$2:D$600,O26) -> 4 | Q26: {=XLOOKUP(O26,Countries!A$2:A$98,Countries!B$2:B$98,"tbd",0)} -> Asia
A27: 48 | B27: Female | C27: Shoa | D27: Chile | E27: No | F27: Yes | G27: Tsunami | I27: Yes | J27: Apr 8, 2024, 10:18 PM | K27: Completed | L27: HySEA | O27: Czechia | P27: =COUNTIF(D$2:D$600,O27) -> 3 | Q27: {=XLOOKUP(O27,Countries!A$2:A$98,Countries!B$2:B$98,"tbd",0)} -> widening countries
A28: 50 | B28: Male | C28: Grupo de Emergencias de Andalucia (GREA) - Junta de Andalucia | D28: Spain | E28: No | F28: No | G28: Tsunami | I28: No | J28: Apr 10, 2024, 1:17 PM | K28: Completed | L28: HySEA | O28: Ghana | P28: =COUNTIF(D$2:D$600,O28) -> 4 | Q28: {=XLOOKUP(O28,Countries!A$2:A$98,Countries!B$2:B$98,"tbd",0)} -> Africa
A29: 21 | B29: Male | C29: UNIVERSITY OF NAPLES FEDERICO II | D29: Italy | E29: Yes | F29: No | G29: Tsunami | I29: No | J29: Apr 5, 2024, 2:34 PM | K29: Completed | L29: HySEA | O29: United Arab Emirates | P29: =COUNTIF(D$2:D$600,O29) -> 2 | Q29: {=XLOOKUP(O29,Countries!A$2:A$98,Countries!B$2:B$98,"tbd",0)} -> Asia
A30: 62 | B30: Male | C30: Edanya Group | D30: Spain | E30: Yes | F30: No | G30: Tsunami | I30: Yes | J30: Apr 23, 2024, 11:06 AM | K30: Completed | L30: HySEA | O30: Costa Rica | P30: =COUNTIF(D$2:D$600,O30) -> 1 | Q30: {=XLOOKUP(O30,Countries!A$2:A$98,Countries!B$2:B$98,"tbd",0)} -> Middle/South America
A31: 33 | B31: Female | C31: NED University of Engineering and Technology | D31: Pakistan | E31: Yes | F31: No | G31: Tsunami | I31: No | J31: Apr 6, 2024, 9:03 AM | K31: Completed | L31: HySEA | O31: Morocco | P31: =COUNTIF(D$2:D$600,O31) -> 6 | Q31: {=XLOOKUP(O31,Countries!A$2:A$98,Countries!B$2:B$98,"tbd",0)} -> Africa
A32: 24 | B32: Female | C32: Instituto de Ciencias del Mar - CSIC | D32: Spain | E32: No | F32: No | G32: Geohazard; Marine Sciences; Solid Earth; Tsunami | H32: Active tectonics and associated geogazards | I32: No | J32: Apr 5, 2024, 3:06 PM | K32: Completed | L32: HySEA | O32: New Zealand | P32: =COUNTIF(D$2:D$600,O32) -> 5 | Q32: {=XLOOKUP(O32,Countries!A$2:A$98,Countries!B$2:B$98,"tbd",0)} -> associated countries
A33: 14 | B33: Female | C33: Universidad Continental | D33: Peru | E33: Yes | F33: No | G33: Computer Science; Tsunami | I33: No | J33: Apr 5, 2024, 12:41 AM | K33: Completed | L33: HySEA | O33: Egypt | P33: =COUNTIF(D$2:D$600,O33) -> 3 | Q33: {=XLOOKUP(O33,Countries!A$2:A$98,Countries!B$2:B$98,"tbd",0)} -> Middle East
A34: 38 | B34: Male | C34: TERC University of Hormozgan | D34: Iran | E34: No | F34: No | G34: Geohazard; Seismology; Tsunami | I34: No | J34: Apr 6, 2024, 8:04 PM | K34: Completed | L34: HySEA | O34: Australia | P34: =COUNTIF(D$2:D$600,O34) -> 1 | Q34: {=XLOOKUP(O34,Countries!A$2:A$98,Countries!B$2:B$98,"tbd",0)} -> Oceania
A35: 10 | B35: Female | C35: International institute of earthquake engineering and seismology | D35: Iran | E35: Yes | F35: Yes | G35: Geohazard; Seismology; Tsunami | I35: No | J35: Apr 2, 2024, 10:41 PM | K35: Completed | L35: HySEA | O35: Norway | P35: =COUNTIF(D$2:D$600,O35) -> 5 | Q35: {=XLOOKUP(O35,Countries!A$2:A$98,Countries!B$2:B$98,"tbd",0)} -> associated countries
A36: 12 | B36: Male | C36: Dinámica Costera | D36: Chile | E36: No | F36: Yes | G36: Engineering; Marine Sciences | I36: No | J36: Apr 4, 2024, 11:46 PM | K36: Completed | L36: HySEA | O36: Colombia | P36: =COUNTIF(D$2:D$600,O36) -> 6 | Q36: {=XLOOKUP(O36,Countries!A$2:A$98,Countries!B$2:B$98,"tbd",0)} -> Middle/South America
A37: 6 | B37: Male | C37: The Geological Survey of Israel | D37: Israel | E37: No | F37: No | G37: Geohazard; Seismology; Solid Earth | I37: Yes | J37: Mar 31, 2024, 12:33 PM | K37: Completed | L37: HySEA | O37: Portugal | P37: =COUNTIF(D$2:D$600,O37) -> 2 | Q37: {=XLOOKUP(O37,Countries!A$2:A$98,Countries!B$2:B$98,"tbd",0)} -> widening countries
A38: 58 | B38: Male | C38: BMKG | D38: Indonesia | E38: Yes | F38: No | G38: Geohazard; Seismology; Solid Earth; Tsunami; Volcanology | H38: Geology | I38: No | J38: Apr 22, 2024, 4:35 AM | K38: Completed | L38: HySEA | O38: Mexico | P38: =COUNTIF(D$2:D$600,O38) -> 2 | Q38: {=XLOOKUP(O38,Countries!A$2:A$98,Countries!B$2:B$98,"tbd",0)} -> Middle/South America
A39: 18 | B39: Male | C39: SHOA | D39: Chile | E39: No | F39: No | G39: Tsunami | I39: Yes | J39: Apr 5, 2024, 1:30 PM | K39: Completed | L39: HySEA | O39: Albania | P39: =COUNTIF(D$2:D$600,O39) -> 4 | Q39: {=XLOOKUP(O39,Countries!A$2:A$98,Countries!B$2:B$98,"tbd",0)} -> associated countries
A40: 2 | B40: Female | C40: GeoSphere Austria | D40: Austria | E40: Yes | F40: No | G40: Atmospheric Physics; Geohazard; Seismology | H40: Physics | I40: No | J40: Mar 20, 2024, 2:40 PM | K40: Completed | L40: HySEA | O40: Hungary | P40: =COUNTIF(D$2:D$600,O40) -> 2 | Q40: {=XLOOKUP(O40,Countries!A$2:A$98,Countries!B$2:B$98,"tbd",0)} -> widening countries
...

Sheet SeisSol_ExaHyPE_WS
A1: ID | B1: Gender | C1: Affiliation | D1: Country Of Affiliation | E1: Are You An Early Career Scientist? | F1: Do You Work In Industry, Start-Up Or Small/Medium Enterprise? | G1: What Is Your Scientific Expertise? (Multiple Choice) | H1: Scientific Expertise - Other(s): | I1: Have you been familiar with any of the involved Geo-INQUIRE services before? | J1: Registration date | K1: How did you hear about this event: | L1: Tags | O1: Countries | P1: No_Countries | Q1: Category
A2: 15 | B2: Female | C2: LMU | D2: Germany | E2: No | F2: No | G2: Seismology | L2: SeisSol_ExaHyPE_WS | O2: {=UNIQUE(D2:D187)} -> Germany | P2: =COUNTIF(D$2:D$120,O2) -> 29 | Q2: {=XLOOKUP(O2,Countries!A$2:A$98,Countries!B$2:B$98,"tbd",0)} -> Europe
A3: 55 | B3: Male | C3: Ghana Atomic Energy Commission | D3: Ghana | E3: Yes | F3: Yes | G3: Data Science; Energy Transformation/Storage; Natural Hazard Management; Marine Geology / Geophysics; Volcanology; Seismology; Tsunami; Geodesy; Remote sensing; Geology; Hydrology | L3: SeisSol_ExaHyPE_WS | O3: Ghana | P3: =COUNTIF(D$2:D$120,O3) -> 1 | Q3: {=XLOOKUP(O3,Countries!A$2:A$98,Countries!B$2:B$98,"tbd",0)} -> Africa
A4: 45 | B4: Male | C4: Technical University of Munich | D4: Germany | E4: No | F4: No | G4: Computer Science | H4: Computational Science and Engineering, Simulation software | L4: SeisSol_ExaHyPE_WS | O4: Ecuador | P4: =COUNTIF(D$2:D$120,O4) -> 1 | Q4: {=XLOOKUP(O4,Countries!A$2:A$98,Countries!B$2:B$98,"tbd",0)} -> Middle/South America
A5: 37 | B5: Male | C5: LRZ | D5: Germany | E5: No | F5: No | G5: Other | H5: Physiker | L5: SeisSol_ExaHyPE_WS | O5: Italy | P5: =COUNTIF(D$2:D$120,O5) -> 5 | Q5: {=XLOOKUP(O5,Countries!A$2:A$98,Countries!B$2:B$98,"tbd",0)} -> Europe
A6: 60 | B6: Male | C6: Earthquake Engineering | D6: Ecuador | E6: Yes | F6: Yes | G6: Computer Science; Data Science; Natural Hazard Management; Seismology; Tsunami; Geodesy; Other | H6: Earthquake resistant systems | L6: SeisSol_ExaHyPE_WS | O6: United States | P6: =COUNTIF(D$2:D$120,O6) -> 6 | Q6: {=XLOOKUP(O6,Countries!A$2:A$98,Countries!B$2:B$98,"tbd",0)} -> U.S. + Canada
A7: 31 | B7: Male | C7: Advanced Micro Devices GmbH | D7: Germany | E7: No | F7: Yes | G7: Computer Science | L7: SeisSol_ExaHyPE_WS | O7: United Kingdom | P7: =COUNTIF(D$2:D$120,O7) -> 5 | Q7: {=XLOOKUP(O7,Countries!A$2:A$98,Countries!B$2:B$98,"tbd",0)} -> associated countries
